<?xml version="1.0"?>
<robot name="thisrobot" xmlns:xacro="http://ros.org/wiki/xacro">
  <!--<link name="base_footprint">
    <visual>
      <geometry>
        <sphere radius="0.2"/>
      </geometry>
    </visual>
  </link>-->

  <link name="base_footprint"/>

  <joint name="base_joint" type="continuous"> <!-- fixed vs. continuous-->
    <parent link="base_footprint"/>
    <child link="laser_mount1"/>
    <origin xyz="0.0 0.0 0.0" rpy="0 0 0"/>
  </joint>

  <link name="laser_mount1">
    <visual>
      <geometry>
        <sphere radius="0.1"/>
      </geometry>
    </visual>
  </link>

  <!--<link name="base_footprint"/>

  <joint name="base_joint" type="fixed">
    <parent link="base_footprint"/>
    <child link="base_link"/>
    <origin xyz="0.0 0.0 0.010" rpy="0 0 0"/>
  </joint>

  <link name="base_link">
    <visual>
      <geometry>
        <sphere radius="0.2"/>
      </geometry>
    </visual>
  </link>-->

  <!--<joint name="scan_joint" type="fixed">
    <parent link="base_link"/>
    <child link="base_scan"/>
    <origin xyz="-0.032 0 0.172" rpy="0 0 0"/>
  </joint>

  <link name="base_scan">
    <visual>
      <origin xyz="0 0 0.0" rpy="0 0 0"/>
      <geometry>
        <sphere radius="0.01"/>
      </geometry>
    </visual>
  </link>-->
</robot>